[2021-06-25 15:05:21,868] {taskinstance.py:876} INFO - Dependencies all met for <TaskInstance: user_processing.creating_table 2021-06-24T00:00:00+00:00 [queued]>
[2021-06-25 15:05:21,877] {taskinstance.py:876} INFO - Dependencies all met for <TaskInstance: user_processing.creating_table 2021-06-24T00:00:00+00:00 [queued]>
[2021-06-25 15:05:21,877] {taskinstance.py:1067} INFO - 
--------------------------------------------------------------------------------
[2021-06-25 15:05:21,877] {taskinstance.py:1068} INFO - Starting attempt 2 of 2
[2021-06-25 15:05:21,878] {taskinstance.py:1069} INFO - 
--------------------------------------------------------------------------------
[2021-06-25 15:05:21,883] {taskinstance.py:1087} INFO - Executing <Task(SqliteOperator): creating_table> on 2021-06-24T00:00:00+00:00
[2021-06-25 15:05:21,887] {standard_task_runner.py:52} INFO - Started process 31204 to run task
[2021-06-25 15:05:21,892] {standard_task_runner.py:76} INFO - Running: ['airflow', 'tasks', 'run', 'user_processing', 'creating_table', '2021-06-24T00:00:00+00:00', '--job-id', '4', '--pool', 'default_pool', '--raw', '--subdir', 'DAGS_FOLDER/user_processing.py', '--cfg-path', '/var/folders/9t/2jnn4bv95w9552ldckktgq900000gn/T/tmpqkevuojb', '--error-file', '/var/folders/9t/2jnn4bv95w9552ldckktgq900000gn/T/tmpu93zq_ao']
[2021-06-25 15:05:21,893] {standard_task_runner.py:77} INFO - Job 4: Subtask creating_table
[2021-06-25 15:05:21,911] {logging_mixin.py:104} INFO - Running <TaskInstance: user_processing.creating_table 2021-06-24T00:00:00+00:00 [running]> on host saidamirs-macbook-pro.local
[2021-06-25 15:05:21,927] {taskinstance.py:1280} INFO - Exporting the following env vars:
AIRFLOW_CTX_DAG_OWNER=airflow
AIRFLOW_CTX_DAG_ID=user_processing
AIRFLOW_CTX_TASK_ID=creating_table
AIRFLOW_CTX_EXECUTION_DATE=2021-06-24T00:00:00+00:00
AIRFLOW_CTX_DAG_RUN_ID=scheduled__2021-06-24T00:00:00+00:00
[2021-06-25 15:05:21,927] {sqlite.py:61} INFO - Executing: 
        CREATE TABLE IF NOT EXIST users (
            firstname TEXT NOT NULL,
            lastname TEXT NOT NULL,
            country TEXT NOT NULL,
            username TEXT NOT NULL,
            password TEXT NOT NULL,
            email TEXT NOT NULL PRIMARY KEY
        )
        
[2021-06-25 15:05:21,929] {base.py:69} INFO - Using connection to: id: db_sqlite. Host: /Users/saidamirmarufkhujaev/airflow/airflow.db, Port: None, Schema: , Login: , Password: None, extra: {}
[2021-06-25 15:05:21,929] {dbapi.py:204} INFO - Running statement: 
        CREATE TABLE IF NOT EXIST users (
            firstname TEXT NOT NULL,
            lastname TEXT NOT NULL,
            country TEXT NOT NULL,
            username TEXT NOT NULL,
            password TEXT NOT NULL,
            email TEXT NOT NULL PRIMARY KEY
        )
        , parameters: []
[2021-06-25 15:05:21,929] {taskinstance.py:1481} ERROR - Task failed with exception
Traceback (most recent call last):
  File "/Users/saidamirmarufkhujaev/venv/lib/python3.9/site-packages/airflow/models/taskinstance.py", line 1137, in _run_raw_task
    self._prepare_and_execute_task_with_callbacks(context, task)
  File "/Users/saidamirmarufkhujaev/venv/lib/python3.9/site-packages/airflow/models/taskinstance.py", line 1311, in _prepare_and_execute_task_with_callbacks
    result = self._execute_task(context, task_copy)
  File "/Users/saidamirmarufkhujaev/venv/lib/python3.9/site-packages/airflow/models/taskinstance.py", line 1341, in _execute_task
    result = task_copy.execute(context=context)
  File "/Users/saidamirmarufkhujaev/venv/lib/python3.9/site-packages/airflow/providers/sqlite/operators/sqlite.py", line 63, in execute
    hook.run(self.sql, parameters=self.parameters)
  File "/Users/saidamirmarufkhujaev/venv/lib/python3.9/site-packages/airflow/hooks/dbapi.py", line 184, in run
    self._run_command(cur, sql_statement, parameters)
  File "/Users/saidamirmarufkhujaev/venv/lib/python3.9/site-packages/airflow/hooks/dbapi.py", line 208, in _run_command
    cur.execute(sql_statement)
sqlite3.OperationalError: near "EXIST": syntax error
[2021-06-25 15:05:21,930] {taskinstance.py:1524} INFO - Marking task as FAILED. dag_id=user_processing, task_id=creating_table, execution_date=20210624T000000, start_date=20210625T100521, end_date=20210625T100521
[2021-06-25 15:05:21,953] {local_task_job.py:151} INFO - Task exited with return code 1
